Workbook

Sheet Inputs
A1: INPUTS & ASSUMPTIONS
A2: Model assumptions drive every output. Any adjustment to inputs will update the analysis dynamically.
B4: ASSUMPTION | C4: VALUE | D4: UNIT | E4: DESCRIPTION
B5: A | PORTFOLIO ASSUMPTIONS
B6: Portfolio Value | C6: 25000000 | D6: USD | E6: Total market value of the concentrated tech portfolio
B7: Estimated Cost Basis | C7: 6500000 | D7: USD | E7: Original acquisition cost of tech holdings
B8: Tech Equity Concentration | C8: 0.9 | D8: % | E8: Percentage of portfolio in single tech sector
B9: Cash & Equivalents Allocation | C9: 0.1 | D9: % | E9: Remaining portfolio in money market / cash
B11: B | TAX RATE ASSUMPTIONS
B12: Fed Long-Term Capital Gains Rate | C12: 0.2 | D12: % | E12: Top federal rate on long-term capital gains
B13: Net Investment Income Tax (NIIT) | C13: 0.038 | D13: % | E13: Medicare surtax on investment income (IRC §1411)
B14: State Income Tax Rate (CA) | C14: 0.133 | D14: % | E14: Highest marginal California income tax rate
B15: Marginal Income Tax Bracket | C15: 0.37 | D15: % | E15: Used for after-tax interest and deduction calculations
B16: Tax-Loss Harvesting Offset | C16: 850000 | D16: USD | E16: Identified losses available to offset realized gains
B18: C | LIQUIDATION PARAMETERS
B19: Number of Tranches | C19: 5 | D19: # | E19: Total liquidation tranches spread over Months 4-8
B20: Tranche Amount (each) | C20: 4500000 | D20: USD | E20: Amount of tech equity liquidated per tranche
B22: D | SECURITIES-BASED LENDING PARAMETERS
B23: SBL Loan Amount | C23: 5000000 | D23: USD | E23: Non-purpose credit line drawn to seed Private Foundation with $5M initial capital
B24: Collateral Pledged | C24: 15000000 | D24: USD | E24: Portfolio value pledged; 40% ($10M) remains unencumbered
B25: SOFR Benchmark Rate | C25: 0.045 | D25: % | E25: Secured Overnight Financing Rate — update as market moves
B26: Credit Spread | C26: 0.02 | D26: % | E26: Institutional pricing spread above SOFR
B27: Margin Call LTV Trigger | C27: 0.4 | D27: % | E27: LTV level at which additional collateral is required
B29: E | GOALS-BASED PLANNING ASSUMPTIONS
B30: Bear Case Gross Return | C30: 0.05 | D30: % | E30: Conservative scenario — stressed market environment
B31: Base Case Gross Return | C31: 0.098 | D31: % | E31: Institutional long-term capital market assumption
B32: Bull Case Gross Return | C32: 0.135 | D32: % | E32: Optimistic scenario — alternatives outperform
B33: Annual Withdrawal Rate | C33: 0.02 | D33: % | E33: Sustainable annual distribution for lifestyle & philanthropy
B34: Planning Horizon (Years) | C34: 20 | D34: Yrs | E34: Long-term compounding window
B35: Private Foundation Target | C35: 10000000 | D35: USD | E35: Target philanthropic endowment value
B36: Foundation Annual Return | C36: 0.075 | D36: % | E36: Expected endowment investment return
B37: Foundation Annual Payout | C37: 0.05 | D37: % | E37: Annual grantmaking as % of foundation assets
B38: Foundation Annual Contribution | C38: 70760 | D38: USD | E38: Annual client contribution from portfolio income; bridges $5M seed to $10M target at Year 20
B39: F | COMPUTED VALUES — Auto-calculated from above. Do not edit.
B40: Unrealized Capital Gains | C40: =C6-C7 -> 18500000 | E40: Portfolio Value − Cost Basis
B41: Gross Effective Tax Rate | C41: =C12+C13+C14 -> 0.371 | E41: Fed + NIIT + State
B42: Estimated Gross Tax Liability | C42: =(C6-C7)*(C12+C13+C14) -> 6863500 | E42: Unrealized Gains × Effective Rate
B43: Net Tax Liability (After Offset) | C43: =(C6-C7)*(C12+C13+C14)-C16 -> 6013500 | E43: Gross Tax − Harvesting Offset
B44: All-In SBL Interest Rate | C44: =C25+C26 -> 0.065 | E44: SOFR + Credit Spread
B45: After-Tax SBL Rate | C45: =(C25+C26)*(1-C15) -> 0.04095 | E45: All-In Rate × (1 − Tax Bracket)
...

Sheet Overview
A1: UHNW PORTFOLIO TRANSITION ANALYSIS
A2: $25M Tech Founder Case Study | Concentrated Equity to Institutional Diversification | February 2026
B4: CLIENT PROFILE
B5: Client Segment | C5: Ultra High Net Worth (UHNW) | $10M+ Investable Assets
B6: Portfolio Value | C6: =Inputs!C6 -> 25000000
B7: Client Type | C7: Technology Founder / Entrepreneur
B8: Primary Challenge | C8: 90% portfolio concentration in single tech sector; $18.5M unrealized gains
B9: Primary Objective | C9: De-risk position, generate income, fund $10M Private Foundation
B11: KEY OUTCOMES: CURRENT vs. OPTIMIZED DIVERSIFIED MODEL
B12: Metric | C12: Current Portfolio | D12: Optimized Model | E12: Improvement
B13: Asset Classes | C13: 2 | D13: 7 | E13: +5 Classes
B14: Portfolio Beta | C14: 1.35 | D14: 0.88 | E14: ↓ 34.8%
B15: Value at Risk (95%) | C15: $4,250,000 | D15: $1,875,000 | E15: ↓ 55.9%
B16: Maximum Drawdown (Est.) | C16: 45.0% | D16: 22.0% | E16: ↓ 51.1%
B17: Concentration Risk Score | C17: 95 / 100 | D17: 15 / 100 | E17: ↓ 84.2%
B18: Sharpe Ratio | C18: 0.38 | D18: 0.68 | E18: ↑ 78.9%
B19: Annual Portfolio Income | C19: $112,500 | D19: $625,000 | E19: ↑ 455%
B20: Correlation to S&P 500 | C20: 0.94 | D20: 0.68 | E20: ↓ 27.7%
B21: Number of Holdings | C21: 8 | D21: 145 | E21: +1,713%
B23: RECOMMENDATION SUMMARY
B24: Phase / Topic | C24: Action & Rationale
B25: Phase 1 (Months 1-3) | C25: Discovery and planning: risk tolerance assessment, cost basis review, CPA consultation, investment policy statement, and transition scenario modeling.
B26: Phase 2 (Months 4-11) | C26: Systematic liquidation across 5 tranches (Months 4-8, $4.5M each; total $22.5M). Concurrent redeployment into optimized model: 55% public equity, 23% fixed income, 20% alternatives (PE + Real Estate), 2% cash. Tax liability: est. $6.86M gross / $6.01M net.
B27: Phase 3 (Months 12-18) | C27: Establish $5M SBL credit facility against diversified portfolio. Seed Private Foundation without triggering additional capital gains. Ongoing rebalancing, tax-loss harvesting ($850K target), and quarterly performance reviews.
B28: Tax Strategy | C28: $850K tax-loss harvesting offset identified. DAF and Opportunity Zone structures available to further reduce net liability.
B29: Goals-Based Planning | C29: 9.8% base-case expected return projects portfolio to approximately $85M at Year 20. Foundation reaches $10.0M target at Year 20: $5M SBL seed compounding at 2.5% net plus $70,760 annual contribution from diversified portfolio income.
B31: Navigate tabs: Inputs | Portfolio Transition | Tax Analysis | SBL Credit | Goals Planning Prepared by: Mario Enrique Mercado | February 2026

Sheet Portfolio Transition
A1: PORTFOLIO TRANSITION ANALYSIS
A2: From Concentrated Risk to Institutional Diversification | $25M Portfolio | February 2026
B4: SECTION A: ASSET ALLOCATION COMPARISON
B5: Asset Class / Sub-Category | C5: Current Alloc % | D5: Current Value ($) | E5: Optimized Model Alloc % | F5: Optimized Model Value ($)
B6: Cash & Equivalents | C6: 0.1 | D6: 2500000 | E6: 0.02 | F6: 500000
B7: Money Market | C7: 0.1 | D7: 2500000 | E7: 0.02 | F7: 500000
B8: Fixed Income | E8: 0.23 | F8: 5750000
B9: High Yield Bonds | E9: 0.05 | F9: 1250000
B10: Investment Grade Bonds | E10: 0.15 | F10: 3750000
B11: Municipal Bonds | E11: 0.03 | F11: 750000
B12: Private Equity | E12: 0.12 | F12: 3000000
B13: Buyout Funds | E13: 0.08 | F13: 2000000
B14: Venture Capital | E14: 0.04 | F14: 1000000
B15: Public Equity | C15: 1.8 | D15: 45000000 | E15: 0.55 | F15: 13750000
B16: Emerging Markets | E16: 0.05 | F16: 1250000
B17: International Developed | E17: 0.12 | F17: 3000000
B18: US Large Cap | E18: 0.25 | F18: 6250000
B19: US Large Cap Tech | C19: 0.9 | D19: 22500000
B20: US Large Cap Tech (90% Concentration) | C20: 0.9 | D20: 22500000
B21: US Mid Cap | E21: 0.08 | F21: 2000000
B22: US Small Cap | E22: 0.05 | F22: 1250000
B23: Real Estate | E23: 0.08 | F23: 2000000
B24: Core Real Estate | E24: 0.05 | F24: 1250000
B25: Real Estate Opportunistic | E25: 0.03 | F25: 750000
B26: TOTAL PORTFOLIO VALUE | C26: 1 | D26: =Inputs!C6 -> 25000000 | E26: 1 | F26: =Inputs!C6 -> 25000000
B28: SECTION B: RISK & RETURN METRICS COMPARISON
B29: Metric | C29: Category | D29: Current Portfolio | E29: Optimized Model | F29: Change / Improvement
B30: Portfolio Beta | C30: Portfolio Risk | D30: 1.35 | E30: 0.88 | F30: ↓ 34.8%
B31: Value at Risk 95% | C31: Portfolio Risk | D31: $4,250,000 | E31: $1,875,000 | F31: ↓ 55.9%
B32: Maximum Drawdown Estimate | C32: Portfolio Risk | D32: 45.0% | E32: 22.0% | F32: ↓ 51.1%
B33: Concentration Risk Score | C33: Portfolio Risk | D33: 95 | E33: 15 | F33: ↓ 84.2%
B34: Expected Annual Return | C34: Return Metrics | D34: 11.7% | E34: 9.8% | F34: ↓ 16.2%
B35: Risk-Adjusted Return | C35: Return Metrics | D35: 0.38 | E35: 0.68 | F35: ↑ 78.9%
B36: Downside Deviation | C36: Return Metrics | D36: 22.5% | E36: 11.2% | F36: ↓ 50.2%
B37: Number of Holdings | C37: Diversification | D37: 8 | E37: 145 | F37: ↑ 1712.5%
B38: Asset Class Count | C38: Diversification | D38: 2 | E38: 7 | F38: ↑ 250.0%
B39: Geographic Exposure | C39: Diversification | D39: 1 | E39: 4 | F39: ↑ 300.0%
B40: Correlation to S&P 500 | C40: Diversification | D40: 0.94 | E40: 0.68 | F40: ↓ 27.7%
... B42: Dividend Yield | C42: Income Generation | D42: 0.5% | E42: 2.5% | F42: ↑ 400.0%

Sheet Tax Analysis
A1: TAX TRANSITION ANALYSIS
A2: Capital Gains Management & Tax-Efficient Liquidation Strategy | February 2026
B4: SECTION A: CAPITAL GAINS OVERVIEW — All values update from Inputs tab
B5: Item | C5: Value | D5: Notes
B6: Current Portfolio Value | C6: =Inputs!C6 -> 25000000 | D6: Source: Inputs tab B6 | Edit there to update all tabs
B7: Estimated Cost Basis | C7: =Inputs!C7 -> 6500000 | D7: Source: Inputs tab B7
B8: Unrealized Capital Gains | C8: =Inputs!C40 -> 18500000 | D8: Portfolio Value − Cost Basis (Inputs C40)
B9: Federal Long-Term Cap Gains Rate | C9: =Inputs!C12 -> 0.2 | D9: Source: Inputs tab C12 | Top federal rate on long-term gains
B10: Net Investment Income Tax (NIIT) | C10: =Inputs!C13 -> 0.038 | D10: Medicare surtax on investment income (IRC §1411) — Inputs C13
B11: State Tax Rate (CA) | C11: =Inputs!C14 -> 0.133 | D11: Highest marginal CA rate — Inputs C14
B12: Gross Effective Rate | C12: =Inputs!C41 -> 0.371 | D12: Fed + NIIT + State (Inputs C41)
B13: Estimated Gross Tax Liability | C13: =Inputs!C42 -> 6863500 | D13: Unrealized Gains × Effective Rate (Inputs C42)
B14: Tax-Loss Harvesting Offset | C14: =0-Inputs!C16 -> -850000 | D14: Identified losses to offset gains — Inputs C16 (displayed as reduction)
B15: Net Tax Liability (After Offset) | C15: =Inputs!C43 -> 6013500 | D15: Gross Tax − Offset (Inputs C43)
B17: SECTION B: PHASED LIQUIDATION SCHEDULE — 5 Tranches Over 8 Months
B18: Tranche / Month | C18: Amount Liquidated | D18: Est. Tax Impact | E18: Cumulative Liquidated
B19: Tranche 1 (Month 4) | C19: =Inputs!C20 -> 4500000 | D19: =Inputs!C20*Inputs!C41 -> 1669500 | E19: =SUM(C19:C19) -> 4500000
B20: Tranche 2 (Month 5) | C20: =Inputs!C20 -> 4500000 | D20: =Inputs!C20*Inputs!C41 -> 1669500 | E20: =SUM(C19:C20) -> 9000000
B21: Tranche 3 (Month 6) | C21: =Inputs!C20 -> 4500000 | D21: =Inputs!C20*Inputs!C41 -> 1669500 | E21: =SUM(C19:C21) -> 13500000
B22: Tranche 4 (Month 7) | C22: =Inputs!C20 -> 4500000 | D22: =Inputs!C20*Inputs!C41 -> 1669500 | E22: =SUM(C19:C22) -> 18000000
B23: Tranche 5 (Month 8) | C23: =Inputs!C20 -> 4500000 | D23: =Inputs!C20*Inputs!C41 -> 1669500 | E23: =SUM(C19:C23) -> 22500000
B24: TOTAL LIQUIDATED | C24: =SUM(C19:C23) -> 22500000 | D24: =SUM(D19:D23) -> 8347500 | E24: =SUM(C19:C23) -> 22500000
B26: SECTION C: TAX OPTIMIZATION STRATEGIES
B27: Strategy | C27: Est. Value | D27: Description
B28: Tax-Loss Harvesting | C28: =Inputs!C16 -> 850000 | D28: Identify offsetting losses in fixed income and other equity positions. Reduces net taxable gain dollar-for-dollar.
B29: Donor-Advised Fund (DAF) | C29: 500000 | D29: Contribute appreciated shares directly to DAF. Avoid capital gains entirely; receive fair-market-value charitable deduction.
B30: Qualified Opportunity Zone (QOZ) | C30: 1000000 | D30: Invest deferred gains into QOZ fund. Defer recognition and potentially exclude future appreciation after 10-year hold.
B31: Installment Liquidation Structure | C31: Structural | D31: 5 monthly tranches across Months 4-8 within a single tax year. To split recognition across two tax years, time the final tranche(s) after December 31.
B32: Charitable Remainder Trust (CRT) | C32: Structural | D32: Transfer appreciated stock into CRT. Avoid immediate gain, receive income stream, estate planning benefit.
B34: All tax figures are estimates. Actual liability depends on cost basis, holding period, filing status, and applicable deductions. Coordinate with qualified CPA and estate attorney before execution. Change portfolio value, cost basis, or tax rates in the Inputs tab to update all figures.

Sheet SBL Credit
A1: SECURITIES-BASED LENDING (SBL) CREDIT FACILITY
A2: $5M Non-Purpose Credit Facility | Private Foundation Funding Strategy | February 2026
B4: SECTION A: CREDIT FACILITY STRUCTURE — Live formulas from Inputs tab
B5: Parameter | C5: Value | D5: Notes
B6: Loan Purpose | C6: Non-Purpose Loan | D6: Proceeds may not purchase or carry securities (Reg U)
B7: Loan Amount | C7: =Inputs!C23 -> 5000000 | D7: Source: Inputs C23 | Change there to update all SBL figures
B8: Collateral Portfolio Value | C8: =Inputs!C24 -> 15000000 | D8: Source: Inputs C24 | 60% of diversified portfolio pledged
B9: Loan-to-Value (LTV) | C9: =Inputs!C23/Inputs!C24 -> 0.33333333 | D9: Loan ÷ Collateral (auto-updates if either changes)
B10: Margin Call Trigger | C10: =Inputs!C27 -> 0.4 | D10: Source: Inputs C27 | LTV level requiring additional collateral
B11: SOFR Benchmark Rate | C11: =Inputs!C25 -> 0.045 | D11: Source: Inputs C25 | Update when market SOFR changes
B12: Credit Spread | C12: =Inputs!C26 -> 0.02 | D12: Source: Inputs C26 | Institutional UHNW pricing
B13: All-In Interest Rate | C13: =Inputs!C44 -> 0.065 | D13: SOFR + Spread (Inputs C44)
B14: Effective After-Tax Rate | C14: =Inputs!C45 -> 0.04095 | D14: All-In × (1 − Tax Bracket) (Inputs C45)
B15: Payment Structure | C15: Interest-Only | D15: No mandatory principal amortization; annual rate resets
B16: Facility Term | C16: 12 Months (Renewable) | D16: Annually renewable at bank's discretion; no prepayment penalty
B17: Annual Gross Interest | C17: =Inputs!C46 -> 325000 | D17: Loan Amount × All-In Rate (Inputs C46)
B18: Annual After-Tax Interest | C18: =Inputs!C47 -> 204750 | D18: Annual Gross × (1 − Tax Bracket) (Inputs C47)
B19: Use of Proceeds | C19: Private Foundation Seed Capital | D19: Fund $10M philanthropic vehicle without triggering capital gains
B21: SECTION B: INTEREST-ONLY PAYMENT SCHEDULE — 12-Month Facility
B22: Period | C22: Beginning Balance | D22: Monthly Interest | E22: Principal Payment | F22: Ending Balance
B23: Month 1 | C23: =Inputs!C23 -> 5000000 | D23: =Inputs!C23*Inputs!C44/12 -> 27083.333 | E23: 0 | F23: =Inputs!C23 -> 5000000
B24: Month 2 | C24: =Inputs!C23 -> 5000000 | D24: =Inputs!C23*Inputs!C44/12 -> 27083.333 | E24: 0 | F24: =Inputs!C23 -> 5000000
B25: Month 3 | C25: =Inputs!C23 -> 5000000 | D25: =Inputs!C23*Inputs!C44/12 -> 27083.333 | E25: 0 | F25: =Inputs!C23 -> 5000000
B26: Month 4 | C26: =Inputs!C23 -> 5000000 | D26: =Inputs!C23*Inputs!C44/12 -> 27083.333 | E26: 0 | F26: =Inputs!C23 -> 5000000
B27: Month 5 | C27: =Inputs!C23 -> 5000000 | D27: =Inputs!C23*Inputs!C44/12 -> 27083.333 | E27: 0 | F27: =Inputs!C23 -> 5000000
B28: Month 6 | C28: =Inputs!C23 -> 5000000 | D28: =Inputs!C23*Inputs!C44/12 -> 27083.333 | E28: 0 | F28: =Inputs!C23 -> 5000000
B29: Month 7 | C29: =Inputs!C23 -> 5000000 | D29: =Inputs!C23*Inputs!C44/12 -> 27083.333 | E29: 0 | F29: =Inputs!C23 -> 5000000
B30: Month 8 | C30: =Inputs!C23 -> 5000000 | D30: =Inputs!C23*Inputs!C44/12 -> 27083.333 | E30: 0 | F30: =Inputs!C23 -> 5000000
B31: Month 9 | C31: =Inputs!C23 -> 5000000 | D31: =Inputs!C23*Inputs!C44/12 -> 27083.333 | E31: 0 | F31: =Inputs!C23 -> 5000000
B32: Month 10 | C32: =Inputs!C23 -> 5000000 | D32: =Inputs!C23*Inputs!C44/12 -> 27083.333 | E32: 0 | F32: =Inputs!C23 -> 5000000
B33: Month 11 | C33: =Inputs!C23 -> 5000000 | D33: =Inputs!C23*Inputs!C44/12 -> 27083.333 | E33: 0 | F33: =Inputs!C23 -> 5000000
B34: Month 12 | C34: =Inputs!C23 -> 5000000 | D34: =Inputs!C23*Inputs!C44/12 -> 27083.333 | E34: 0 | F34: =Inputs!C23 -> 5000000
B35: TOTAL ANNUAL INTEREST | C35: =Inputs!C23 -> 5000000 | D35: =SUM(D23:D34) -> 325000 | E35: 0 | F35: =Inputs!C23 -> 5000000
B37: SECTION C: MARGIN CALL STRESS TEST
B38: Scenario | C38: Collateral Decline | D38: Collateral Value | E38: Resulting LTV | F38: Margin Call Triggered?
B39: Base Case | C39: 0% (Baseline) | D39: =Inputs!C24*(1-0) -> 15000000 | E39: =Inputs!C23/(Inputs!C24*(1-0)) -> 0.33333333 | F39: =IF(Inputs!C23/(Inputs!C24*(1-0))>Inputs!C27,"YES","NO") -> NO
B40: Moderate Decline | C40: -10% | D40: =Inputs!C24*(1-0.1) -> 13500000 | E40: =Inputs!C23/(Inputs!C24*(1-0.1)) -> 0.37037037 | F40: =IF(Inputs!C23/(Inputs!C24*(1-0.1))>Inputs!C27,"YES","NO") -> NO
B41: Significant Drop | C41: -20% | D41: =Inputs!C24*(1-0.2) -> 12000000 | E41: =Inputs!C23/(Inputs!C24*(1-0.2)) -> 0.41666667 | F41: =IF(Inputs!C23/(Inputs!C24*(1-0.2))>Inputs!C27,"YES","NO") -> YES
B42: Severe Stress | C42: -30% | D42: =Inputs!C24*(1-0.3) -> 10500000 | E42: =Inputs!C23/(Inputs!C24*(1-0.3)) -> 0.47619048 | F42: =IF(Inputs!C23/(Inputs!C24*(1-0.3))>Inputs!C27,"YES","NO") -> YES
B43: 2008-Style Crisis | C43: -40% | D43: =Inputs!C24*(1-0.4) -> 9000000 | E43: =Inputs!C23/(Inputs!C24*(1-0.4)) -> 0.55555556 | F43: =IF(Inputs!C23/(Inputs!C24*(1-0.4))>Inputs!C27,"YES","NO") -> YES
...

Sheet Goals Planning
A1: GOALS-BASED WEALTH PLANNING
A2: $10M Private Foundation | 20-Year Portfolio Projection | Bear / Base / Bull Scenarios | February 2026
B4: SECTION A: PLANNING ASSUMPTIONS — All values pull from Inputs tab
B5: Parameter | C5: Bear Case | D5: Base Case | E5: Bull Case | F5: Notes
B6: Starting Portfolio Value | C6: =Inputs!C48 -> 18986500 | D6: =Inputs!C48 -> 18986500 | E6: =Inputs!C48 -> 18986500 | F6: Net of estimated tax after harvesting offset (Inputs C48)
B7: Expected Gross Annual Return | C7: =Inputs!C30 -> 0.05 | D7: =Inputs!C31 -> 0.098 | E7: =Inputs!C32 -> 0.135 | F7: Edit individual scenario returns in Inputs E30-E32
B8: Annual Withdrawal Rate | C8: =Inputs!C33 -> 0.02 | D8: =Inputs!C33 -> 0.02 | E8: =Inputs!C33 -> 0.02 | F8: Inputs E33 | Applied uniformly across all scenarios
B9: Net Annual Growth Rate | C9: =Inputs!C49 -> 0.03 | D9: =Inputs!C50 -> 0.078 | E9: =Inputs!C51 -> 0.115 | F9: Return minus Withdrawal Rate (Inputs C49-C51) — drives the projection
B10: Investment Horizon | C10: 20 Years | D10: 20 Years | E10: 20 Years | F10: Inputs E34
B11: Private Foundation Target | C11: =Inputs!C35 -> 10000000 | D11: =Inputs!C35 -> 10000000 | E11: =Inputs!C35 -> 10000000 | F11: Inputs E35 | Philanthropic endowment goal
B12: Foundation Funding Method | C12: SBL Facility | D12: SBL Facility | E12: SBL Facility | F12: $5M drawn from credit line — zero liquidation, zero additional tax
B13: Annual SBL Interest Cost | C13: =Inputs!C47 -> 204750 | D13: =Inputs!C47 -> 204750 | E13: =Inputs!C47 -> 204750 | F13: After-tax interest (Inputs C47) — updates with rate or loan changes
B15: SECTION B: 20-YEAR PORTFOLIO PROJECTION — Each year = prior year × (1 + net rate). Change Inputs to reprice instantly.
B16: Year | C16: Calendar Year | D16: Bear Case (Net 3.0%) | E16: Base Case (Net 7.8%) | F16: Bull Case (Net 11.5%) | G16: Milestone
B17: Year 1 | C17: 2027 | D17: =Inputs!C48*(1+Inputs!C49) -> 19556095 | E17: =Inputs!C48*(1+Inputs!C50) -> 20467447 | F17: =Inputs!C48*(1+Inputs!C51) -> 21169948 | G17: SBL Facility Established
B18: Year 2 | C18: 2028 | D18: =D17*(1+Inputs!C49) -> 20142778 | E18: =E17*(1+Inputs!C50) -> 22063908 | F18: =F17*(1+Inputs!C51) -> 23604491
B19: Year 3 | C19: 2029 | D19: =D18*(1+Inputs!C49) -> 20747061 | E19: =E18*(1+Inputs!C50) -> 23784893 | F19: =F18*(1+Inputs!C51) -> 26319008
B20: Year 4 | C20: 2030 | D20: =D19*(1+Inputs!C49) -> 21369473 | E20: =E19*(1+Inputs!C50) -> 25640114 | F20: =F19*(1+Inputs!C51) -> 29345694
B21: Year 5 | C21: 2031 | D21: =D20*(1+Inputs!C49) -> 22010557 | E21: =E20*(1+Inputs!C50) -> 27640043 | F21: =F20*(1+Inputs!C51) -> 32720449 | G21: 5-Year Review
B22: Year 6 | C22: 2032 | D22: =D21*(1+Inputs!C49) -> 22670874 | E22: =E21*(1+Inputs!C50) -> 29795967 | F22: =F21*(1+Inputs!C51) -> 36483300
B23: Year 7 | C23: 2033 | D23: =D22*(1+Inputs!C49) -> 23351000 | E23: =E22*(1+Inputs!C50) -> 32120052 | F23: =F22*(1+Inputs!C51) -> 40678880
B24: Year 8 | C24: 2034 | D24: =D23*(1+Inputs!C49) -> 24051530 | E24: =E23*(1+Inputs!C50) -> 34625416 | F24: =F23*(1+Inputs!C51) -> 45356951
B25: Year 9 | C25: 2035 | D25: =D24*(1+Inputs!C49) -> 24773076 | E25: =E24*(1+Inputs!C50) -> 37326198 | F25: =F24*(1+Inputs!C51) -> 50573000
B26: Year 10 | C26: 2036 | D26: =D25*(1+Inputs!C49) -> 25516268 | E26: =E25*(1+Inputs!C50) -> 40237642 | F26: =F25*(1+Inputs!C51) -> 56388895 | G26: Foundation Self-Sustaining
B27: Year 11 | C27: 2037 | D27: =D26*(1+Inputs!C49) -> 26281756 | E27: =E26*(1+Inputs!C50) -> 43376178 | F27: =F26*(1+Inputs!C51) -> 62873618
B28: Year 12 | C28: 2038 | D28: =D27*(1+Inputs!C49) -> 27070209 | E28: =E27*(1+Inputs!C50) -> 46759520 | F28: =F27*(1+Inputs!C51) -> 70104085
B29: Year 13 | C29: 2039 | D29: =D28*(1+Inputs!C49) -> 27882315 | E29: =E28*(1+Inputs!C50) -> 50406762 | F29: =F28*(1+Inputs!C51) -> 78166054
B30: Year 14 | C30: 2040 | D30: =D29*(1+Inputs!C49) -> 28718785 | E30: =E29*(1+Inputs!C50) -> 54338490 | F30: =F29*(1+Inputs!C51) -> 87155150
B31: Year 15 | C31: 2041 | D31: =D30*(1+Inputs!C49) -> 29580348 | E31: =E30*(1+Inputs!C50) -> 58576892 | F31: =F30*(1+Inputs!C51) -> 97177993 | G31: 15-Year Review
B32: Year 16 | C32: 2042 | D32: =D31*(1+Inputs!C49) -> 30467759 | E32: =E31*(1+Inputs!C50) -> 63145890 | F32: =F31*(1+Inputs!C51) -> 1.0835346e+08
B33: Year 17 | C33: 2043 | D33: =D32*(1+Inputs!C49) -> 31381792 | E33: =E32*(1+Inputs!C50) -> 68071269 | F33: =F32*(1+Inputs!C51) -> 1.2081411e+08
B34: Year 18 | C34: 2044 | D34: =D33*(1+Inputs!C49) -> 32323245 | E34: =E33*(1+Inputs!C50) -> 73380828 | F34: =F33*(1+Inputs!C51) -> 1.3470773e+08
B35: Year 19 | C35: 2045 | D35: =D34*(1+Inputs!C49) -> 33292943 | E35: =E34*(1+Inputs!C50) -> 79104533 | F35: =F34*(1+Inputs!C51) -> 1.5019912e+08
B36: Year 20 | C36: 2046 | D36: =D35*(1+Inputs!C49) -> 34291731 | E36: =E35*(1+Inputs!C50) -> 85274686 | F36: =F35*(1+Inputs!C51) -> 1.6747202e+08 | G36: ▲ Planning Horizon
B37: 20-YEAR ENDING VALUE | C37: 2046 | D37: =D36 -> 34291731 | E37: =E36 -> 85274686 | F37: =F36 -> 1.6747202e+08 | G37: End of Planning Horizon
B39: SECTION C: PRIVATE FOUNDATION FUNDING ANALYSIS
B40: Milestone | C40: Year | D40: Foundation Value | E40: Cumulative Grants | F40: Endowment Status | G40: Notes
B41: SBL Proceeds Deployed | C41: Year 1 | D41: =Inputs!C23 -> 5000000 | E41: 0 | F41: Foundation Seeded | G41: 100% via SBL — zero additional liquidation. $70,760/yr contribution begins Year 1.
B42: Foundation — Year 5 | C42: Year 5 | D42: =Inputs!C23*(1+(Inputs!C36-Inputs!C37))^5+Inputs!C38*((1+(Inputs!C36-Inputs!C37))^5-1)/(Inputs!C36-Inputs!C37) -> 6028978.9 | E42: =Inputs!C23*Inputs!C37*5 -> 1250000 | F42: Growing | G42: 7.5% return net of 5% grantmaking + $70,760/yr client contribution
B43: Foundation — Year 10 | C43: Year 10 | D43: =Inputs!C23*(1+(Inputs!C36-Inputs!C37))^10+Inputs!C38*((1+(Inputs!C36-Inputs!C37))^10-1)/(Inputs!C36-Inputs!C37) -> 7193174 | E43: =Inputs!C23*Inputs!C37*10 -> 2500000 | F43: Growing | G43: Projected $7.2M at Year 10 — seed + annual contributions
...
